Workbook
Name Cash_Minimum: #REF!
Name Start_Date: #REF!

Sheet HuongDan
A1: HƯỚNG DẪN SỬ DỤNG - MẪU DỰ TOÁN CHI PHÍ PHẦN MỀM NỘI BỘ
A2: Theo NĐ 45/2026/NĐ-CP, QĐ 671/QĐ-BTTTT, QĐ 320/QĐ-BKHCN, QĐ 1688/QĐ-BTTTT
A4: I. CẤU TRÚC WORKBOOK
A5: Sheet | B5: Chức năng | C5: Thao tác
A6: HuongDan | B6: Hướng dẫn sử dụng (sheet này) | C6: Chỉ đọc
A7: TongDuToan | B7: Bảng tổng hợp dự toán toàn dự án (GPM+GQL+GTV+GK+GDP) | C7: Tự động từ các sheet khác
A8: TongHop | B8: Tổng hợp chi phí phần mềm nội bộ (G, C, TL, GPM) | C8: Tự động
A9: ChiPhi_G1 | B9: Tính chi phí trực tiếp G = 1,4 × E × P × H | C9: Tự động từ PL4–7 + PL8
A10: PL1_Actors | B10: Danh sách tác nhân (Actors) | C10: ⭐ NHẬP LIỆU
A11: PL2 | B11: Danh sách yêu cầu chức năng | C11: ⭐ NHẬP LIỆU
A12: PL3 | B12: Chuyển đổi yêu cầu CN → Use Case | C12: ⭐ NHẬP LIỆU
A13: PL4_TAW | B13: Tính điểm tác nhân (TAW) | C13: ⭐ NHẬP LIỆU số actor
A14: PL5_TBF | B14: Tính điểm Use Case (TBF) với hệ số BMT | C14: ⭐ NHẬP LIỆU số UC
A15: PL6_TCF | B15: Hệ số phức tạp KT-CN (TCF) | C15: ⭐ NHẬP LIỆU xếp hạng Fi
A16: PL7_ECF | B16: Hệ số môi trường (ECF) | C16: ⭐ NHẬP LIỆU xếp hạng Fi
A17: PL8_Luong | B17: Bảng tính lương nhân công (H) theo QĐ 320 | C17: ⭐ NHẬP LIỆU HCB, MLCS, số NC
B18: Ghi chú: ⭐ = các sheet cần nhập liệu khi áp dụng cho dự án mới
A20: II. CÁC BƯỚC THỰC HIỆN KHI ÁP DỤNG CHO DỰ ÁN MỚI
A21: Bước | B21: Thao tác | C21: Giải thích
A22: 1 | B22: Cập nhật thông tin dự án | C22: Sửa Tên dự án, Chủ đầu tư tại TongDuToan (B3, D3)
A23: 2 | B23: Xác định Actors (PL1_Actors) | C23: Liệt kê tác nhân, phân loại (Đơn giản/Trung bình/Phức tạp), gán trọng số (1/2/3)
A24: 3 | B24: Nhập số Actor (PL4_TAW) | C24: Nhập số lượng Actor theo từng loại: Đơn giản, Trung bình, Phức tạp → TAW tự động
A25: 4 | B25: Xác định Use Case (PL2 → PL3 → PL5_TBF) | C25: Liệt kê yêu cầu CN, chuyển sang UC, phân loại BMT, nhập số UC vào PL5 → TBF tự động
A26: 5 | B26: Chấm điểm hệ số KT-CN (PL6_TCF) | C26: Chấm Fi (0-5) cho 13 hệ số KT-CN → TFW → TCF tự động tính
A27: 6 | B27: Chấm điểm hệ số môi trường (PL7_ECF) | C27: Chấm Fi (0-5) cho 8 hệ số môi trường → EFW → ECF và P (nội suy) tự động
A28: 7 | B28: Cập nhật lương nhân công (PL8_Luong) | C28: Nhập HCB, MLCS, HĐC theo bảng lương hiện hành; nhập số nhân công → H tự động
A29: 8 | B29: Kiểm tra kết quả (ChiPhi_G1) | C29: Kiểm tra AUCP, E, G đã tự động cập nhật. G = 1,4 × E × P × H
A30: 9 | B30: Cập nhật tỷ lệ % (TongDuToan) | C30: Tra QĐ 1688 để xác định GQL%, GTV1% theo quy mô GPM của dự án mới
A31: 10 | B31: Nhập chi phí kiểm thử (TongDuToan) | C31: Lập dự toán riêng cho GKT, GKTATTT rồi nhập vào ô E13:E14
A32: 11 | B32: → Kết quả: TỔNG DỰ TOÁN tự động | C32: TongDuToan!G21 = Tổng chi phí toàn dự án (sau thuế)
A34: III. CÔNG THỨC CHÍNH
A35: Công thức | B35: Diễn giải | C35: Văn bản
A36: UUCP = TAW + TBF | B36: Điểm UC chưa hiệu chỉnh = Điểm Actor + Điểm Use Case | C36: QĐ 671
A37: TCF = 0,6 + 0,01 × TFW | B37: Hệ số phức tạp kỹ thuật-công nghệ | C37: QĐ 671
A38: EF = 1,4 + (-0,03) × EFW | B38: Hệ số môi trường | C38: QĐ 671
A39: AUCP = UUCP × TCF × EF | B39: Điểm UC sau hiệu chỉnh | C39: QĐ 671
A40: E = 10/6 × AUCP | B40: Giá trị nỗ lực thực tế | C40: QĐ 671
A41: G = 1,4 × E × P × H | B41: Chi phí trực tiếp XD, PT, MR phần mềm nội bộ | C41: QĐ 671
A42: C = G × 65% | B42: Chi phí chung | C42: TT 04/2020
A43: TL = (G + C) × 6% | B43: Thu nhập chịu thuế tính trước | C43: TT 04/2020
...

Sheet HD_PL8
A1: HƯỚNG DẪN XÂY DỰNG BẢNG DỰ TOÁN PL8_LUONG
A2: Bảng tính lương nhân công theo phương pháp UCP - QĐ 320/QĐ-BKHCN ngày 30/3/2025
A4: MỤC ĐÍCH
A5: Tính mức lương lao động bình quân (H) - đơn giá giờ công bình quân (đồng/giờ) - làm đầu vào cho công thức G = 1,4 x E x P x H tại sheet ChiPhi_G1.
A6: Kết quả H được liên kết tự động: PL8_Luong → ChiPhi_G1 → TongHop → TongDuToan. Bạn chỉ cần nhập đúng dữ liệu đầu vào.
A8: SLIDE 1: CẤU TRÚC BẢNG PL8_LUONG
A10: STT | B10: Hạng mục | C10: Ký hiệu / Công thức | D10: Loại ô
A11: 1 | B11: Hệ số cấp bậc (HCB) | C11: HCB: tra QĐ 320/QĐ-BKHCN | D11: NHẬP LIỆU
A12: 2 | B12: Hệ số phụ cấp lương (HPC) | C12: HPC: thường = 0 | D12: NHẬP LIỆU
A13: 3 | B13: Mức lương cơ sở (MLCS) | C13: MLCS: theo NĐ hiện hành | D13: NHẬP LIỆU
A14: 4 | B14: Lương cơ bản (LCB) | C14: LCB = HCB x MLCS | D14: CÔNG THỨC
A15: 5 | B15: Hệ số điều chỉnh (HĐC) | C15: HĐC: theo NĐ 74/2024 (0,9) | D15: NHẬP LIỆU
A16: 6 | B16: BHXH + BHYT + BHTN | C16: 21,5% x LCB | D16: CÔNG THỨC
A17: 7 | B17: Số ngày công (t) | C17: t = 26 ngày (QĐ 320) | D17: NHẬP LIỆU
A18: 8 | B18: Giá ngày công (GNC) | C18: [(HCB+HPC) x MLCS x (1+HĐC)+BHLĐ] / t | D18: CÔNG THỨC
A19: 9 | B19: Giá giờ công (GGC) | C19: GGC = GNC / 8 | D19: CÔNG THỨC
A20: 10 | B20: Số nhân công theo bậc | C20: Nhập theo thực tế dự án | D20: NHẬP LIỆU
A21: 11 | B21: Lương BQ có trọng số (H) | C21: SUMPRODUCT(GGC x NC) / SUM(NC) | D21: KẾT QUẢ
A23: SLIDE 2: CÁC Ô NHẬP LIỆU (INPUT) - CHỈ SỬA CÁC Ô NÀY
A25: Ô nhập | B25: Vị trí trong PL8 | C25: Giá trị hiện tại (ví dụ) | D25: Căn cứ pháp lý
A26: HCB | B26: E5:G5 (Kỹ sư bậc 1/2/3) | C26: 2,34 / 2,65 / 2,96 | D26: QĐ 320/QĐ-BKHCN ngày 30/3/2025
A27: HPC | B27: E6:G6 (Kỹ sư bậc 1/2/3) | C27: 0 / 0 / 0 | D27: Theo quy định đơn vị
A28: MLCS | B28: E7:G7 (Kỹ sư bậc 1/2/3) | C28: 2.340.000 đ | D28: NĐ 73/2024/NĐ-CP ngày 30/6/2024
A29: HDC | B29: E9:G9 (Kỹ sư bậc 1/2/3) | C29: 0,9 / 0,9 / 0,9 | D29: NĐ 74/2024/NĐ-CP (hệ số 0,9)
A30: t | B30: E14:G14 (Kỹ sư bậc 1/2/3) | C30: 26 ngày | D30: QĐ 320/QĐ-BKHCN
A31: So NC | B31: E17:G17 (Kỹ sư bậc 1/2/3) | C31: 2 / 0 / 0 (nhập theo dự án) | D31: Theo dự án thực tế
A33: SLIDE 3: CÔNG THỨC TÍNH TOÁN CHI TIẾT
A35: Bước | B35: Công thức | C35: Ví dụ tính (Kỹ sư bậc 1) | D35: Ô trong PL8
A36: B1 | B36: LCB = HCB x MLCS | C36: 2,34 x 2.340.000 = 5.475.600 | D36: E8
A37: B2 | B37: BHXH = 17,5% x LCB | C37: 17,5% x 5.475.600 = 958.230 | D37: E11
A38: B3 | B38: BHYT = 3% x LCB | C38: 3% x 5.475.600 = 164.268 | D38: E12
A39: B4 | B39: BHTN = 1% x LCB | C39: 1% x 5.475.600 = 54.756 | D39: E13
A40: B5 | B40: GNC = [(HCB+HPC)xMLCSx(1+HDC)+BHLD]/t | C40: [(2,34+0)x2.340.000x(1+0,9)+1.177.254]/26 | D40: E15
A41: B6 | B41: GGC = GNC / 8 | C41: 445.419 / 8 = 55.677 | D41: E16
A42: B7 | B42: H = SUMPRODUCT(GGC x NC) / SUM(NC) | C42: 55.677 x 2 / 2 = 55.677 đ/giờ | D42: E18
A44: SLIDE 4: QUY TRÌNH TỪNG BƯỚC
A46: Bước | B46: Thao tác | C46: Chi tiết | D46: Kết quả
A47: 1 | B47: Xác định bậc kỹ sư | C47: Xem dự án cần bao nhiêu bậc (1/2/3), mỗi bậc bao nhiêu người | D47: Danh sách nhân sự dự án
A48: 2 | B48: Nhập HCB vào E5:G5 | C48: Tra QĐ 320/QĐ-BKHCN: Bậc 1=2,34; Bậc 2=2,65; Bậc 3=2,96 | D48: LCB tự động tính
A49: 3 | B49: Nhập MLCS vào E7:G7 | C49: Theo NĐ 73/2024: 2.340.000 đ/tháng (cập nhật khi NĐ mới) | D49: LCB, BHXH tự cập nhật
...

Sheet TongHop
A1: BẢNG TÍNH DỰ TOÁN CHI PHÍ PHẦN MỀM NỘI BỘ
A2: (Theo Quyết định số 671/QĐ-BTTTT ngày 26/04/2024 của Bộ TT&TT)
A3: Căn cứ NĐ 45/2026/NĐ-CP ngày 26/01/2026 (thay thế NĐ 73/2019, NĐ 82/2024)
A4: Tên dự án/Nhiệm vụ: | C4: Thí điểm Hệ thống trí tuệ nhân tạo nội bộ trong công tác văn phòng cấp ủy
A5: Chủ đầu tư: | C5: Văn phòng Thành ủy Đà Nẵng
A7: BẢNG TỔNG HỢP CHI PHÍ PHẦN MỀM NỘI BỘ
A8: TT | B8: Khoản mục chi phí | C8: Cách tính | D8: Ký hiệu | E8: Thành tiền (đồng)
A9: 1 | B9: Chi phí trực tiếp XD, PT, MR phần mềm nội bộ | C9: G = 1,4 × E × P × H | D9: G | E9: =ChiPhi_G1!E14 -> 4.8253423e+08
A10: 2 | B10: Chi phí chung | C10: G × 65% | D10: C | E10: =E9*D19 -> 3.1364725e+08
A11: 3 | B11: Thu nhập chịu thuế tính trước | C11: (G + C) × 6% | D11: TL | E11: =(E9+E10)*D18 -> 47770889
A12: 4 | B12: Chi phí XD, PT, MR phần mềm nội bộ | C12: G + C + TL | D12: GPM | E12: =E9+E10+E11 -> 8.4395238e+08
A13: 5 | B13: Chi phí dự phòng | C13: Theo quy định | D13: Gdp | E13: =E12*D20 -> 84395238
B14: TỔNG CỘNG | C14: Gpm = GPM + Gdp | D14: Gpm | E14: =E12+E13 -> 9.2834761e+08
A17: THÔNG SỐ BỔ SUNG
A18: 1 | B18: Tỷ lệ thu nhập chịu thuế tính trước (TL) | C18: TL = (G+C) × 6% | D18: 0.06 | E18: Theo TT04/2020
A19: 2 | B19: Tỷ lệ chi phí chung | C19: C = G × 65% | D19: 0.65 | E19: Theo TT04/2020
A20: 3 | B20: Tỷ lệ chi phí dự phòng | C20: Gdp = GPM × 10% | D20: 0.1 | E20: Theo NĐ 45/2026

Sheet TongDuToan
A1: BẢNG TỔNG HỢP DỰ TOÁN
A2: (Theo NĐ 45/2026/NĐ-CP, QĐ 671/QĐ-BTTTT, QĐ 1688/QĐ-BTTTT)
A3: Tên dự án: | B3: Xây dựng AI hỗ trợ soạn thảo văn bản hành chính ứng dụng mô hình RAG | C3: Chủ đầu tư: | D3: Văn phòng Thành ủy Đà Nẵng
A4: Stt | B4: Nội dung chi phí | C4: Ký hiệu | D4: Công thức | E4: Giá trị trước thuế | F4: VAT | G4: Giá trị sau thuế
A5: I | B5: Chi phí phần mềm nội bộ | C5: GPM | D5: Theo QĐ 671/QĐ-BTTTT | E5: =TongHop!E14 -> 9.2834761e+08 | G5: =E5 -> 9.2834761e+08
A6: II | B6: Chi phí quản lý dự án | C6: GQL | D6: GPM × tỷ lệ % | E6: =E5*E25 -> 17220848 | G6: =E6 -> 17220848
A7: III | B7: Chi phí tư vấn đầu tư | C7: GTV | D7: GTV1+GTV2+GTV3+GTV4 | E7: =SUM(E8:E11) -> 41791853 | F7: =SUM(F8:F11) -> 600000 | G7: =E7+F7 -> 42391853
A8: 1 | B8: Chi phí lập báo cáo kinh tế - kỹ thuật | C8: GTV1 | D8: GPM × tỷ lệ %, min 10tr | E8: =MAX(E5*E26,10000000) -> 33791853 | G8: =E8 -> 33791853
A9: 2 | B9: Chi phí thẩm tra dự toán | C9: GTV2 | D9: GPM × tỷ lệ %, min 2tr | E9: =MAX(E5*E27,2000000) -> 2000000 | G9: =E9 -> 2000000
A10: 3 | B10: Chi phí lập hồ sơ mời thầu | C10: GTV3 | D10: GPM × tỷ lệ %, min 3tr | E10: =MAX(E5*E28,3000000) -> 3000000 | F10: =E10*E31 -> 300000 | G10: =E10+F10 -> 3300000
A11: 4 | B11: Chi phí đánh giá hồ sơ dự thầu | C11: GTV4 | D11: GPM × tỷ lệ %, min 3tr | E11: =MAX(E5*E29,3000000) -> 3000000 | F11: =E11*E31 -> 300000 | G11: =E11+F11 -> 3300000
A12: IV | B12: Chi phí khác | C12: GK | E12: =SUM(E13:E16) -> 5000000 | F12: =SUM(F13:F16) -> 500000 | G12: =E12+F12 -> 5500000
A13: 1 | B13: Chi phí kiểm thử chức năng PM | C13: GKT | D13: Lập dự toán | E13: 0 | G13: =E13 -> 0
A14: 2 | B14: Chi phí kiểm thử ATANTT | C14: GKTATTT | D14: Lập dự toán | E14: 0 | G14: =E14 -> 0
A15: 3 | B15: Chi phí thẩm định HSMT | C15: GK1 | D15: GPM × 0,1%, min 2tr | E15: =MAX(E5*0.1%,2000000) -> 2000000 | F15: =E15*E31 -> 200000 | G15: =E15+F15 -> 2200000
A16: 4 | B16: Chi phí thẩm định kết quả đấu thầu | C16: GK2 | D16: GPM × 0,1%, min 3tr | E16: =MAX(E5*0.1%,3000000) -> 3000000 | F16: =E16*E31 -> 300000 | G16: =E16+F16 -> 3300000
A17: V | B17: Chi phí dự phòng | C17: GDP | D17: (GPM+GQL+GTV+GK)×10% | E17: =(E5+E6+E7+E12)*E30 -> 99236031 | G17: =E17 -> 99236031
B20: Đơn vị: đồng Việt Nam
B21: TỔNG CỘNG | C21: G | D21: GPM+GQL+GTV+GK+GDP | E21: =E5+E6+E7+E12+E17 -> 1.0915963e+09 | F21: =F7+F12 -> 1100000 | G21: =E21+F21 -> 1.0926963e+09
A23: THÔNG SỐ TỶ LỆ
A24: TT | B24: Thông số | C24: Ký hiệu | D24: Văn bản | E24: Tỷ lệ (%)
A25: 1 | B25: Tỷ lệ chi phí quản lý dự án | C25: GQL | D25: QĐ 1688/QĐ-BTTTT (Bảng số 1) | E25: 0.01855
A26: 2 | B26: Tỷ lệ lập BCKTKT | C26: GTV1 | D26: QĐ 1688/QĐ-BTTTT (Bảng số 2) | E26: 0.0364
A27: 3 | B27: Tỷ lệ thẩm tra dự toán | C27: GTV2 | D27: QĐ 1688/QĐ-BTTTT (Bảng số 2) | E27: 0.00085
A28: 4 | B28: Tỷ lệ lập HSMT | C28: GTV3 | D28: NĐ 214/2025/NĐ-CP | E28: 0.002
A29: 5 | B29: Tỷ lệ đánh giá HSDT | C29: GTV4 | D29: NĐ 214/2025/NĐ-CP | E29: 0.002
A30: 6 | B30: Tỷ lệ dự phòng | C30: GDP | D30: NĐ 45/2026/NĐ-CP | E30: 0.1
A31: 7 | B31: Thuế suất VAT | C31: VAT | D31: Luật thuế GTGT hiện hành | E31: 0.1
A33: (*) | B33: Các ô màu xanh dương là ô nhập liệu - Cần tra bảng QĐ 1688/QĐ-BTTTT để xác định tỷ lệ % chính xác theo quy mô GPM của dự án
A34: (*) | B34: Chi phí kiểm thử (GKT, GKTATTT) cần lập dự toán riêng theo CV 3787/BTTTT-THH và TT 121/2018/TT-BTC

Sheet PL1_Actors
A1: PHỤ LỤC I: DANH SÁCH CÁC TÁC NHÂN (ACTORS)
A2: TT | B2: Tên tác nhân | C2: Mô tả tác nhân | D2: Phân loại tác nhân | E2: Trọng số | F2: Ghi chú
A3: 1 | B3: Quản trị viên | C3: Quản lý toàn diện hệ thống: Khởi tạo tài khoản, phân quyền, cấu hình tham số lõi của AI (System Prompt, Temperature), giám sát tài nguyên máy chủ (GPU/RAM) và hiệu đính tri thức để tinh chỉnh mô hình. | D3: Phức tạp | E3: 3
A4: 2 | B4: Chuyên viên Văn thư | C4: Chịu trách nhiệm về đầu vào dữ liệu (Data Ingestion): Tải lên văn bản pháp quy mới, vận hành và giám sát các tiến trình tự động như Crawler, OCR, bóc tách Metadata và véc-tơ hóa tri thức. | D4: Phức tạp | E4: 3
A5: 3 | B5: Chuyên viên Nghiệp vụ | C5: Là người dùng lõi khai thác sức mạnh AI: Sử dụng Web Chat để truy vấn RAG, tra cứu sơ đồ đồ thị pháp lý, xem tài liệu song song (Split-viewer), đánh giá phản hồi AI và kết xuất dự thảo hành chính. | D5: Trung bình | E5: 2
A6: 4 | B6: Lãnh đạo cơ quan | C6: Khai thác thông tin quản trị cấp cao: Xem Dashboard thống kê, theo dõi tần suất sử dụng AI của các phòng ban và kiểm tra tỷ lệ ảo giác/lỗi của hệ thống. | D6: Đơn giản | E6: 1
A7: Ghi chú: Đơn giản (trọng số 1) - Trung bình (trọng số 2) - Phức tạp (trọng số 3)

Sheet PL2_YeuCau
A1: PHỤ LỤC II: DANH SÁCH YÊU CẦU CHỨC NĂNG
A2: TT | B2: Mô tả yêu cầu | C2: Phân loại (B/M/T) | D2: Số giao dịch | E2: Ghi chú
A3: 1 | B3: Đăng nhập phân hệ Quản trị | C3: M | D3: 5 | E3: Nhóm I
A4: 2 | B4: Quản lý danh mục Nhóm quyền | C4: M | D4: 6 | E4: Nhóm I
A5: 3 | B5: Quản lý danh mục Chức năng hệ thống | C5: M | D5: 5 | E5: Nhóm I
A6: 4 | B6: Phân quyền truy cập cho người dùng | C6: T | D6: 8 | E6: Nhóm I
A7: 5 | B7: Quản lý danh sách tài khoản người dùng (Thêm, sửa, xóa, khóa) | C7: M | D7: 6 | E7: Nhóm I
A8: 6 | B8: Quản lý cấu hình tham số AI (Model, Nhiệt độ sinh từ, System Prompt) | C8: M | D8: 6 | E8: Nhóm I
A9: 7 | B9: Quản lý Kho tri thức pháp quy (Upload tài liệu nội bộ, xóa tài liệu) | C9: T | D9: 8 | E9: Nhóm I
A10: 8 | B10: Quản lý tiến trình thu thập và đồng bộ dữ liệu tự động (Crawler Job) | C10: M | D10: 5 | E10: Nhóm I
A11: 9 | B11: Quản lý tiến trình Vector hóa (Giám sát Chunking & Embedding) | C11: M | D11: 5 | E11: Nhóm I
A12: 10 | B12: Quản lý danh mục Lời nhắc mẫu (Prompt Templates) dùng chung | C12: M | D12: 5 | E12: Nhóm I
A13: 11 | B13: Quản lý và hiệu đính Phản hồi AI (Review Feedback & Correct Ground Truth) | C13: T | D13: 8 | E13: Nhóm I
A14: 12 | B14: Nhật ký sử dụng hệ thống (Lịch sử đăng nhập, lịch sử Chat) | C14: M | D14: 5 | E14: Nhóm I
... A32: 30 | B32: Kết xuất tệp tin văn bản hành chính (.docx, .pdf) theo chuẩn NĐ30 | C32: T | D32: 8 | E32: Nhóm II
A33: Ghi chú: B (Bé) = ≤3 giao dịch; M (Trung bình) = 4–7 giao dịch; T (To) = ≥8 giao dịch

Sheet PL3_UseCase
A1: PHỤ LỤC III: BẢNG CHUYỂN ĐỔI YÊU CẦU CHỨC NĂNG SANG USE CASE
A2: TT | B2: Tên Use Case | C2: Tên tác nhân | D2: Số giao dịch | E2: Phân loại BMT | F2: Phân loại độ phức tạp | G2: Ghi chú
A3: 1 | B3: Đăng nhập phân hệ Quản trị | C3: Quản trị viên | D3: Trung bình | E3: M | F3: Trung bình | G3: YCCN 01
A4: 2 | B4: Quản lý danh mục Nhóm quyền | C4: Quản trị viên | D4: Trung bình | E4: M | F4: Trung bình | G4: YCCN 02
A5: 3 | B5: Quản lý danh mục Chức năng hệ thống | C5: Quản trị viên | D5: Trung bình | E5: M | F5: Trung bình | G5: YCCN 03
A6: 4 | B6: Phân quyền truy cập cho người dùng | C6: Quản trị viên | D6: Phức tạp | E6: T | F6: Phức tạp | G6: YCCN 04
A7: 5 | B7: Quản lý danh sách tài khoản người dùng | C7: Quản trị viên | D7: Trung bình | E7: M | F7: Trung bình | G7: YCCN 05
A8: 6 | B8: Quản lý cấu hình tham số AI (Model, Nhiệt độ sinh từ, System Prompt) | C8: Quản trị viên | D8: Trung bình | E8: M | F8: Trung bình | G8: YCCN 06
A9: 7 | B9: Quản lý Kho tri thức pháp quy (Upload tài liệu nội bộ, xóa tài liệu) | C9: Chuyên viên Văn thư | D9: Phức tạp | E9: T | F9: Phức tạp | G9: YCCN 07
A10: 8 | B10: Quản lý tiến trình thu thập và đồng bộ dữ liệu tự động (Crawler Job) | C10: Quản trị viên | D10: Trung bình | E10: M | F10: Trung bình | G10: YCCN 08
A11: 9 | B11: Quản lý tiến trình Vector hóa (Giám sát Chunking & Embedding) | C11: Quản trị viên | D11: Trung bình | E11: M | F11: Trung bình | G11: YCCN 09
A12: 10 | B12: Quản lý danh mục Lời nhắc mẫu (Prompt Templates) dùng chung | C12: Quản trị viên | D12: Trung bình | E12: M | F12: Trung bình | G12: YCCN 10
A13: 11 | B13: Quản lý và hiệu đính Phản hồi AI (Review Feedback & Correct Ground Truth) | C13: Chuyên viên Văn thư | D13: Phức tạp | E13: T | F13: Phức tạp | G13: YCCN 11
A14: 12 | B14: Nhật ký sử dụng hệ thống (Lịch sử đăng nhập, lịch sử Chat) | C14: Quản trị viên | D14: Trung bình | E14: M | F14: Trung bình | G14: YCCN 12
... A32: 30 | B32: Kết xuất tệp tin văn bản hành chính (.docx, .pdf) theo chuẩn NĐ30 | C32: Chuyên viên Nghiệp vụ | D32: Phức tạp | E32: T | F32: Phức tạp | G32: YCCN 30
A33: Ghi chú: Đơn giản ≤3 GD; Trung bình 4-7 GD; Phức tạp ≥8 GD

Sheet PL4_TAW
A1: PHỤ LỤC IV: TÍNH ĐIỂM TÁC NHÂN KHÔNG HIỆU CHỈNH (TAW)
A2: TT | B2: Loại Actor | C2: Trọng số | D2: Số tác nhân | E2: Điểm | F2: Ghi chú
A3: 1 | B3: Đơn giản | C3: 1 | D3: 1 | E3: =C3*D3 -> 1
A4: 2 | B4: Trung bình | C4: 2 | D4: 1 | E4: =C4*D4 -> 2
A5: 3 | B5: Phức tạp | C5: 3 | D5: 2 | E5: =C5*D5 -> 6
B6: Cộng (1+2+3) | D6: =SUM(D3:D5) -> 4 | E6: =SUM(E3:E5) -> 9
B7: TAW | E7: =E6 -> 9 | F7: Tổng điểm tác nhân không hiệu chỉnh

Sheet PL5_TBF
A1: PHỤ LỤC V: TÍNH ĐIỂM CÁC TRƯỜNG HỢP SỬ DỤNG (USE CASE)
A2: STT | B2: Loại | C2: Trọng số | D2: Hệ số BMT | E2: Số UC | F2: Điểm
A3: 1 | B3: B - Đơn giản | C3: 5 | D3: 1 | E3: 2 | F3: =C3*D3*E3 -> 10
B4: B - Trung bình | C4: 10 | D4: 1 | E4: 0 | F4: =C4*D4*E4 -> 0
B5: B - Phức tạp | C5: 15 | D5: 1 | E5: 0 | F5: =C5*D5*E5 -> 0
A6: 2 | B6: M - Đơn giản | C6: 5 | D6: 1.2 | E6: 19 | F6: =C6*D6*E6 -> 114
B7: M - Trung bình | C7: 10 | D7: 1.2 | E7: 0 | F7: =C7*D7*E7 -> 0
B8: M - Phức tạp | C8: 15 | D8: 1.2 | E8: 0 | F8: =C8*D8*E8 -> 0
A9: 3 | B9: T - Đơn giản | C9: 5 | D9: 1.5 | E9: 9 | F9: =C9*D9*E9 -> 67.5
B10: T - Trung bình | C10: 10 | D10: 1.5 | E10: 0 | F10: =C10*D10*E10 -> 0
B11: T - Phức tạp | C11: 15 | D11: 1.5 | E11: 0 | F11: =C11*D11*E11 -> 0
B12: Cộng (1+2+3) | E12: =SUM(E3:E11) -> 30 | F12: =SUM(F3:F11) -> 191.5
B13: TBF | F13: =F12 -> 191.5
A15: Ghi chú: Trọng số theo QĐ 671: ĐG=5, TB=10, PT=15
A16: Hệ số BMT: B=1, M=1.2, T=1.5

Sheet PL6_TCF
A1: PHỤ LỤC VI: HỆ SỐ PHỨC TẠP KỸ THUẬT - CÔNG NGHỆ (TCF)
A2: TT | B2: Các hệ số KT-CN | C2: Trọng số (Wi) | D2: Giá trị xếp hạng (Fi) | E2: Kết quả (Wi×Fi) | F2: Ghi chú
B3: I. Hệ số KT-CN (TFW)
A4: T1 | B4: Xử lý phân tán | C4: 2 | D4: 2 | E4: =C4*D4 -> 4 | F4: 0-5
A5: T2 | B5: Mức độ quan trọng của hiệu năng | C5: 1 | D5: 4 | E5: =C5*D5 -> 4 | F5: 0-5
A6: T3 | B6: Hiệu quả sử dụng cho người dùng | C6: 1 | D6: 3 | E6: =C6*D6 -> 3 | F6: 0-5
A7: T4 | B7: Độ phức tạp của xử lý bên trong | C7: 1 | D7: 4 | E7: =C7*D7 -> 4 | F7: 0-5
A8: T5 | B8: Khả năng tái sử dụng mã nguồn | C8: 1 | D8: 2 | E8: =C8*D8 -> 2 | F8: 0-5
A9: T6 | B9: Dễ cài đặt | C9: 0.5 | D9: 2 | E9: =C9*D9 -> 1 | F9: 0-5
A10: T7 | B10: Dễ vận hành | C10: 0.5 | D10: 3 | E10: =C10*D10 -> 1.5 | F10: 0-5
A11: T8 | B11: Khả năng chuyển đổi | C11: 2 | D11: 1 | E11: =C11*D11 -> 2 | F11: 0-5
A12: T9 | B12: Dễ dàng bảo trì | C12: 1 | D12: 2 | E12: =C12*D12 -> 2 | F12: 0-5
A13: T10 | B13: Xử lý đồng thời | C13: 1 | D13: 4 | E13: =C13*D13 -> 4 | F13: 0-5
A14: T11 | B14: Mức độ hỗ trợ bảo mật | C14: 1 | D14: 4 | E14: =C14*D14 -> 4 | F14: 0-5
A15: T12 | B15: Sự phụ thuộc vào mã lệnh bên thứ ba | C15: 1 | D15: 3 | E15: =C15*D15 -> 3 | F15: 0-5
A16: T13 | B16: Mức độ hỗ trợ đào tạo người sử dụng | C16: 1 | D16: 3 | E16: =C16*D16 -> 3 | F16: 0-5
B17: TFW = Tổng (Wi × Fi) | E17: =SUM(E4:E16) -> 37.5
B18: II. Hệ số phức tạp KT-CN (TCF)
B19: TCF = 0.6 + (0.01 × TFW) | E19: =0.6+(0.01*E17) -> 0.975 | F19: Hệ số phức tạp KT-CN
B21: UUCP = TAW + TBF | E21: =PL4_TAW!E7+PL5_TBF!F13 -> 200.5 | F21: Điểm UC chưa hiệu chỉnh
B22: AUCP = UUCP × TCF × EF | E22: =E21*E19*PL7_ECF!E12 -> 185.71312 | F22: ĐIỂM USE CASE SAU HIỆU CHỈNH

Sheet PL7_ECF
A1: PHỤ LỤC VII: HỆ SỐ TÁC ĐỘNG MÔI TRƯỜNG, NHÓM LÀM VIỆC (ECF)
A2: TT | B2: Các hệ số môi trường | C2: Trọng số (Wi) | D2: Giá trị xếp hạng (Fi) | E2: Kết quả (Wi×Fi) | F2: Ghi chú
A3: E1 | B3: Quen thuộc với quy trình phát triển PM | C3: 1.5 | D3: 2 | E3: =C3*D3 -> 3 | F3: 0-5
A4: E2 | B4: Kinh nghiệm về ứng dụng | C4: 0.5 | D4: 2 | E4: =C4*D4 -> 1 | F4: 0-5
A5: E3 | B5: Kinh nghiệm về hướng đối tượng | C5: 1 | D5: 3 | E5: =C5*D5 -> 3 | F5: 0-5
A6: E4 | B6: Năng lực chủ trì phân tích | C6: 0.5 | D6: 2 | E6: =C6*D6 -> 1 | F6: 0-5
A7: E5 | B7: Động lực làm việc | C7: 1 | D7: 5 | E7: =C7*D7 -> 5 | F7: 0-5
A8: E6 | B8: Yêu cầu ổn định | C8: 2 | D8: 3 | E8: =C8*D8 -> 6 | F8: 0-5
A9: E7 | B9: Nhân viên bán thời gian | C9: -1 | D9: 2 | E9: =C9*D9 -> -2 | F9: 0-5
A10: E8 | B10: Ngôn ngữ lập trình khó | C10: -1 | D10: 2 | E10: =C10*D10 -> -2 | F10: 0-5
B11: EFW = Tổng (Wi × Fi) | E11: =SUM(E3:E10) -> 15
B12: ECF = 1.4 + (-0.03 × EFW) | E12: =1.4+(-0.03*E11) -> 0.95 | F12: Hệ số môi trường
A14: Ghi chú: Giá trị xếp hạng Fi từ 0 đến 5 (0 = không liên quan, 5 = rất quan trọng)

Sheet PL8_Luong
A1: PHỤ LỤC VIII: BẢNG TÍNH LƯƠNG NHÂN CÔNG
A2: (Theo QĐ số 320/QĐ-BKHCN ngày 30/3/2025 của Bộ KH&CN)
A4: TT | B4: Hạng mục | C4: Ký hiệu | D4: Cách tính | E4: Kỹ sư bậc 1 | F4: Kỹ sư bậc 2 | G4: Kỹ sư bậc 3 | H4: Ghi chú
A5: 1 | B5: Hệ số cấp bậc | C5: HCB | E5: 2.34 | F5: 2.65 | G5: 2.96 | H5: QĐ 320/QĐ-BKHCN ngày 30/3/2025
A6: 2 | B6: Hệ số phụ cấp lương | C6: HPC | E6: 0 | F6: 0 | G6: 0
A7: 3 | B7: Mức lương cơ sở | C7: MLCS | E7: 2340000 | F7: 2340000 | G7: 2340000 | H7: NĐ 73/2024/NĐ-CP ngày 30/6/2024
A8: 4 | B8: Lương cơ bản | C8: LCB | D8: HCB × MLCS | E8: =E5*E7 -> 5475600 | F8: =F5*F7 -> 6201000 | G8: =G5*G7 -> 6926400
A9: 5 | B9: Hệ số điều chỉnh tăng thêm tiền lương | C9: HĐC | E9: 0.9 | F9: 0.9 | G9: 0.9 | H9: NĐ 74/2024/NĐ-CP (Hệ số 0,9)
A10: 6 | B10: Các khoản đóng góp theo lương | C10: BHLĐ | D10: BHXH + BHYT + BHTN | E10: =E11+E12+E13 -> 1177254 | F10: =F11+F12+F13 -> 1333215 | G10: =G11+G12+G13 -> 1489176 | H10: QĐ 320/QĐ-BKHCN
A11: 6.1 | B11: Bảo hiểm xã hội (17,5%) | C11: BHXH | D11: 17,5% × LCB | E11: =17.5%*E8 -> 958230 | F11: =17.5%*F8 -> 1085175 | G11: =17.5%*G8 -> 1212120 | H11: NĐ 58/2020/NĐ-CP
A12: 6.2 | B12: Bảo hiểm y tế (3%) | C12: BHYT | D12: 3% × LCB | E12: =3%*E8 -> 164268 | F12: =3%*F8 -> 186030 | G12: =3%*G8 -> 207792 | H12: QĐ 595/QĐ-BHXH
A13: 6.3 | B13: Bảo hiểm thất nghiệp (1%) | C13: BHTN | D13: 1% × LCB | E13: =1%*E8 -> 54756 | F13: =1%*F8 -> 62010 | G13: =1%*G8 -> 69264 | H13: QĐ 595/QĐ-BHXH
A14: 7 | B14: Số ngày công trong tháng | C14: t | E14: 26 | F14: 26 | G14: 26 | H14: QĐ 320/QĐ-BKHCN
A15: 8 | B15: Giá ngày công | C15: GNC | D15: [(HCB+HPC)×MLCS×(1+HĐC)+BHLĐ]/t | E15: =((E5+E6)*E7*(1+E9)+E10)/E14 -> 445419 | F15: =((F5+F6)*F7*(1+F9)+F10)/F14 -> 504427.5 | G15: =((G5+G6)*G7*(1+G9)+G10)/G14 -> 563436 | H15: QĐ 320/QĐ-BKHCN
A16: 9 | B16: Giá giờ công | C16: GGC | D16: GNC / 8 | E16: =E15/8 -> 55677.375 | F16: =F15/8 -> 63053.438 | G16: =G15/8 -> 70429.5
A17: 10 | B17: Số nhân công | E17: 2 | F17: 0 | G17: 0 | H17: Nhập theo dự án
A18: 11 | B18: Mức lương lao động bình quân (H) | C18: H | D18: BQ có trọng số theo số NC | E18: =IF(SUM(E17:G17)=0,0,SUMPRODUCT(E16:G16,E17:G17)/SUM(E17:G17)) -> 55677.375 | H18: Đơn giá giờ công BQ (đồng/giờ)

Sheet ChiPhi_G1
A1: TÍNH TOÁN CHI PHÍ TRỰC TIẾP XÂY DỰNG, PHÁT TRIỂN, MỞ RỘNG PHẦN MỀM NỘI BỘ
A3: TT | B3: Hạng mục | C3: Diễn giải | D3: Ký hiệu | E3: Giá trị | F3: Ghi chú
A4: I | B4: Tính điểm trường hợp sử dụng (Use case)
A5: 1 | B5: Điểm Actor (TAW) | C5: Phụ lục IV | D5: TAW | E5: =PL4_TAW!E7 -> 9
A6: 2 | B6: Điểm Use case (TBF) | C6: Phụ lục V | D6: TBF | E6: =PL5_TBF!F13 -> 191.5
A7: 3 | B7: Tính điểm UUCP | C7: UUCP = TAW + TBF | D7: UUCP | E7: =E5+E6 -> 200.5
A8: 4 | B8: Hệ số phức tạp KT-CN (TCF) | C8: TCF = 0,6 + (0,01 × TFW) | D8: TCF | E8: =PL6_TCF!E19 -> 0.975 | F8: Phụ lục VI
A9: 5 | B9: Hệ số phức tạp môi trường (EF) | C9: EF = 1,4 + (-0,03 × EFW) | D9: EF | E9: =PL7_ECF!E12 -> 0.95 | F9: Phụ lục VII
A10: 6 | B10: Tính điểm AUCP | C10: AUCP = UUCP × TCF × EF | D10: AUCP | E10: =E7*E8*E9 -> 185.71312
A11: II | B11: Nội suy thời gian lao động (P) | C11: Giờ công/điểm UC | D11: P | E11: 20 | F11: Nội suy từ PL VII (20-28 giờ)
A12: III | B12: Giá trị nỗ lực thực tế (E) | C12: E = 10/6 × AUCP | D12: E | E12: =10/6*E10 -> 309.52187 | F12: Hệ số điều chỉnh nỗ lực
A13: IV | B13: Mức lương lao động BQ (H) | C13: đồng/giờ | D13: H | E13: =PL8_Luong!E18 -> 55677.375 | F13: Theo QĐ 320/QĐ-BKHCN (Phụ lục VIII)
A14: V | B14: Chi phí trực tiếp PM nội bộ (G) | C14: G = 1,4 × E × P × H | D14: G | E14: =1.4*E12*E11*E13 -> 4.8253423e+08 | F14: đồng
